{"content": {"suites": {"0": {"status": {"total_pass": 2, "total_skip": 0, "total_xpass": 0, "total_xfail": 0, "total_rerun": 0, "total_fail": 0, "total_error": 0}, "tests": {"0": {"status": "PASS", "message": "", "test_name": "test_catalog_stock_validation_process", "rerun": "0"}, "1": {"status": "PASS", "message": "", "test_name": "test_catalog_stock_rejection_process", "rerun": "0"}}, "suite_name": "tests/suites/test_inventory_management_suite.py"}, "1": {"suite_name": "tests/suites/test_order_management_suite.py", "tests": {"0": {"status": "FAIL", "message": "           TimeoutError: [WinError 10060] A connection attempt failed because the connected party did not properly respond after a period of time, or established connection failed because connected host has failed to respond\n       urllib3.exceptions.ConnectTimeoutError: (<urllib3.connection.HTTPConnection object at 0x0000019834D71420>, 'Connection to host.docker.internal timed out. (connect timeout=None)')\n       urllib3.exceptions.MaxRetryError: HTTPConnectionPool(host='host.docker.internal', port=5105): Max retries exceeded with url: /Account/Login?ReturnUrl=%2Fconnect%2Fauthorize%2Fcallback%3Fresponse_type%3Dtoken%26client_id%3Dorderingswaggerui%26redirect_uri%3Dhttp%253A%252F%252Fhost.docker.internal%253A5102%252Fswagger%252Foauth2-redirect.html%26scope%3Dorders%26state%3DTW9uIE1hciAwNiAyMDIzIDE1OjI5OjA4IEdNVCswMjAwIChJc3JhZWwgU3RhbmRhcmQgVGltZSk%253D (Caused by ConnectTimeoutError(<urllib3.connection.HTTPConnection object at 0x0000019834D71420>, 'Connection to host.docker.internal timed out. (connect timeout=None)'))\n               requests.exceptions.ConnectTimeout: HTTPConnectionPool(host='host.docker.internal', port=5105): Max retries exceeded with url: /Account/Login?ReturnUrl=%2Fconnect%2Fauthorize%2Fcallback%3Fresponse_type%3Dtoken%26client_id%3Dorderingswaggerui%26redirect_uri%3Dhttp%253A%252F%252Fhost.docker.internal%253A5102%252Fswagger%252Foauth2-redirect.html%26scope%3Dorders%26state%3DTW9uIE1hciAwNiAyMDIzIDE1OjI5OjA4IEdNVCswMjAwIChJc3JhZWwgU3RhbmRhcmQgVGltZSk%253D (Caused by ConnectTimeoutError(<urllib3.connection.HTTPConnection object at 0x0000019834D71420>, 'Connection to host.docker.internal timed out. (connect timeout=None)'))\n", "test_name": "test_mss", "rerun": "0"}, "1": {"status": "PASS", "message": "", "test_name": "test_user_can_submit_an_order", "rerun": "0"}, "2": {"status": "FAIL", "message": "           TimeoutError: [WinError 10060] A connection attempt failed because the connected party did not properly respond after a period of time, or established connection failed because connected host has failed to respond\n       urllib3.exceptions.ConnectTimeoutError: (<urllib3.connection.HTTPConnection object at 0x0000019835265E70>, 'Connection to host.docker.internal timed out. (connect timeout=None)')\n       urllib3.exceptions.MaxRetryError: HTTPConnectionPool(host='host.docker.internal', port=5105): Max retries exceeded with url: /Account/Login?ReturnUrl=%2Fconnect%2Fauthorize%2Fcallback%3Fresponse_type%3Dtoken%26client_id%3Dorderingswaggerui%26redirect_uri%3Dhttp%253A%252F%252Fhost.docker.internal%253A5102%252Fswagger%252Foauth2-redirect.html%26scope%3Dorders%26state%3DTW9uIE1hciAwNiAyMDIzIDE1OjI5OjA4IEdNVCswMjAwIChJc3JhZWwgU3RhbmRhcmQgVGltZSk%253D (Caused by ConnectTimeoutError(<urllib3.connection.HTTPConnection object at 0x0000019835265E70>, 'Connection to host.docker.internal timed out. (connect timeout=None)'))\n               requests.exceptions.ConnectTimeout: HTTPConnectionPool(host='host.docker.internal', port=5105): Max retries exceeded with url: /Account/Login?ReturnUrl=%2Fconnect%2Fauthorize%2Fcallback%3Fresponse_type%3Dtoken%26client_id%3Dorderingswaggerui%26redirect_uri%3Dhttp%253A%252F%252Fhost.docker.internal%253A5102%252Fswagger%252Foauth2-redirect.html%26scope%3Dorders%26state%3DTW9uIE1hciAwNiAyMDIzIDE1OjI5OjA4IEdNVCswMjAwIChJc3JhZWwgU3RhbmRhcmQgVGltZSk%253D (Caused by ConnectTimeoutError(<urllib3.connection.HTTPConnection object at 0x0000019835265E70>, 'Connection to host.docker.internal timed out. (connect timeout=None)'))\n", "test_name": "test_user_can_cancel_order_on_status_1", "rerun": "0"}, "3": {"status": "FAIL", "message": "           TimeoutError: [WinError 10060] A connection attempt failed because the connected party did not properly respond after a period of time, or established connection failed because connected host has failed to respond\n       urllib3.exceptions.ConnectTimeoutError: (<urllib3.connection.HTTPConnection object at 0x0000019834E241C0>, 'Connection to host.docker.internal timed out. (connect timeout=None)')\n       urllib3.exceptions.MaxRetryError: HTTPConnectionPool(host='host.docker.internal', port=5105): Max retries exceeded with url: /Account/Login?ReturnUrl=%2Fconnect%2Fauthorize%2Fcallback%3Fresponse_type%3Dtoken%26client_id%3Dorderingswaggerui%26redirect_uri%3Dhttp%253A%252F%252Fhost.docker.internal%253A5102%252Fswagger%252Foauth2-redirect.html%26scope%3Dorders%26state%3DTW9uIE1hciAwNiAyMDIzIDE1OjI5OjA4IEdNVCswMjAwIChJc3JhZWwgU3RhbmRhcmQgVGltZSk%253D (Caused by ConnectTimeoutError(<urllib3.connection.HTTPConnection object at 0x0000019834E241C0>, 'Connection to host.docker.internal timed out. (connect timeout=None)'))\n               requests.exceptions.ConnectTimeout: HTTPConnectionPool(host='host.docker.internal', port=5105): Max retries exceeded with url: /Account/Login?ReturnUrl=%2Fconnect%2Fauthorize%2Fcallback%3Fresponse_type%3Dtoken%26client_id%3Dorderingswaggerui%26redirect_uri%3Dhttp%253A%252F%252Fhost.docker.internal%253A5102%252Fswagger%252Foauth2-redirect.html%26scope%3Dorders%26state%3DTW9uIE1hciAwNiAyMDIzIDE1OjI5OjA4IEdNVCswMjAwIChJc3JhZWwgU3RhbmRhcmQgVGltZSk%253D (Caused by ConnectTimeoutError(<urllib3.connection.HTTPConnection object at 0x0000019834E241C0>, 'Connection to host.docker.internal timed out. (connect timeout=None)'))\n", "test_name": "test_user_can_cancel_order_on_status_2", "rerun": "0"}, "4": {"status": "FAIL", "message": "           TimeoutError: [WinError 10060] A connection attempt failed because the connected party did not properly respond after a period of time, or established connection failed because connected host has failed to respond\n       urllib3.exceptions.ConnectTimeoutError: (<urllib3.connection.HTTPConnection object at 0x000001983524ACB0>, 'Connection to host.docker.internal timed out. (connect timeout=None)')\n       urllib3.exceptions.MaxRetryError: HTTPConnectionPool(host='host.docker.internal', port=5105): Max retries exceeded with url: /Account/Login?ReturnUrl=%2Fconnect%2Fauthorize%2Fcallback%3Fresponse_type%3Dtoken%26client_id%3Dorderingswaggerui%26redirect_uri%3Dhttp%253A%252F%252Fhost.docker.internal%253A5102%252Fswagger%252Foauth2-redirect.html%26scope%3Dorders%26state%3DTW9uIE1hciAwNiAyMDIzIDE1OjI5OjA4IEdNVCswMjAwIChJc3JhZWwgU3RhbmRhcmQgVGltZSk%253D (Caused by ConnectTimeoutError(<urllib3.connection.HTTPConnection object at 0x000001983524ACB0>, 'Connection to host.docker.internal timed out. (connect timeout=None)'))\n               requests.exceptions.ConnectTimeout: HTTPConnectionPool(host='host.docker.internal', port=5105): Max retries exceeded with url: /Account/Login?ReturnUrl=%2Fconnect%2Fauthorize%2Fcallback%3Fresponse_type%3Dtoken%26client_id%3Dorderingswaggerui%26redirect_uri%3Dhttp%253A%252F%252Fhost.docker.internal%253A5102%252Fswagger%252Foauth2-redirect.html%26scope%3Dorders%26state%3DTW9uIE1hciAwNiAyMDIzIDE1OjI5OjA4IEdNVCswMjAwIChJc3JhZWwgU3RhbmRhcmQgVGltZSk%253D (Caused by ConnectTimeoutError(<urllib3.connection.HTTPConnection object at 0x000001983524ACB0>, 'Connection to host.docker.internal timed out. (connect timeout=None)'))\n", "test_name": "test_user_can_cancel_order_on_status_3", "rerun": "0"}, "5": {"status": "FAIL", "message": "           TimeoutError: [WinError 10060] A connection attempt failed because the connected party did not properly respond after a period of time, or established connection failed because connected host has failed to respond\n       urllib3.exceptions.ConnectTimeoutError: (<urllib3.connection.HTTPConnection object at 0x000001983512AB60>, 'Connection to host.docker.internal timed out. (connect timeout=None)')\n       urllib3.exceptions.MaxRetryError: HTTPConnectionPool(host='host.docker.internal', port=5105): Max retries exceeded with url: /Account/Login?ReturnUrl=%2Fconnect%2Fauthorize%2Fcallback%3Fresponse_type%3Dtoken%26client_id%3Dorderingswaggerui%26redirect_uri%3Dhttp%253A%252F%252Fhost.docker.internal%253A5102%252Fswagger%252Foauth2-redirect.html%26scope%3Dorders%26state%3DTW9uIE1hciAwNiAyMDIzIDE1OjI5OjA4IEdNVCswMjAwIChJc3JhZWwgU3RhbmRhcmQgVGltZSk%253D (Caused by ConnectTimeoutError(<urllib3.connection.HTTPConnection object at 0x000001983512AB60>, 'Connection to host.docker.internal timed out. (connect timeout=None)'))\n               requests.exceptions.ConnectTimeout: HTTPConnectionPool(host='host.docker.internal', port=5105): Max retries exceeded with url: /Account/Login?ReturnUrl=%2Fconnect%2Fauthorize%2Fcallback%3Fresponse_type%3Dtoken%26client_id%3Dorderingswaggerui%26redirect_uri%3Dhttp%253A%252F%252Fhost.docker.internal%253A5102%252Fswagger%252Foauth2-redirect.html%26scope%3Dorders%26state%3DTW9uIE1hciAwNiAyMDIzIDE1OjI5OjA4IEdNVCswMjAwIChJc3JhZWwgU3RhbmRhcmQgVGltZSk%253D (Caused by ConnectTimeoutError(<urllib3.connection.HTTPConnection object at 0x000001983512AB60>, 'Connection to host.docker.internal timed out. (connect timeout=None)'))\n", "test_name": "test_user_can_not_cancel_order_on_status_4", "rerun": "0"}, "6": {"status": "FAIL", "message": "           TimeoutError: [WinError 10060] A connection attempt failed because the connected party did not properly respond after a period of time, or established connection failed because connected host has failed to respond\n       urllib3.exceptions.ConnectTimeoutError: (<urllib3.connection.HTTPConnection object at 0x00000198351212D0>, 'Connection to host.docker.internal timed out. (connect timeout=None)')\n       urllib3.exceptions.MaxRetryError: HTTPConnectionPool(host='host.docker.internal', port=5105): Max retries exceeded with url: /Account/Login?ReturnUrl=%2Fconnect%2Fauthorize%2Fcallback%3Fresponse_type%3Dtoken%26client_id%3Dorderingswaggerui%26redirect_uri%3Dhttp%253A%252F%252Fhost.docker.internal%253A5102%252Fswagger%252Foauth2-redirect.html%26scope%3Dorders%26state%3DTW9uIE1hciAwNiAyMDIzIDE1OjI5OjA4IEdNVCswMjAwIChJc3JhZWwgU3RhbmRhcmQgVGltZSk%253D (Caused by ConnectTimeoutError(<urllib3.connection.HTTPConnection object at 0x00000198351212D0>, 'Connection to host.docker.internal timed out. (connect timeout=None)'))\n               requests.exceptions.ConnectTimeout: HTTPConnectionPool(host='host.docker.internal', port=5105): Max retries exceeded with url: /Account/Login?ReturnUrl=%2Fconnect%2Fauthorize%2Fcallback%3Fresponse_type%3Dtoken%26client_id%3Dorderingswaggerui%26redirect_uri%3Dhttp%253A%252F%252Fhost.docker.internal%253A5102%252Fswagger%252Foauth2-redirect.html%26scope%3Dorders%26state%3DTW9uIE1hciAwNiAyMDIzIDE1OjI5OjA4IEdNVCswMjAwIChJc3JhZWwgU3RhbmRhcmQgVGltZSk%253D (Caused by ConnectTimeoutError(<urllib3.connection.HTTPConnection object at 0x00000198351212D0>, 'Connection to host.docker.internal timed out. (connect timeout=None)'))\n", "test_name": "test_user_can_not_cancel_order_on_status_5", "rerun": "0"}, "7": {"status": "FAIL", "message": "           TimeoutError: [WinError 10060] A connection attempt failed because the connected party did not properly respond after a period of time, or established connection failed because connected host has failed to respond\n       urllib3.exceptions.ConnectTimeoutError: (<urllib3.connection.HTTPConnection object at 0x0000019834E25EA0>, 'Connection to host.docker.internal timed out. (connect timeout=None)')\n       urllib3.exceptions.MaxRetryError: HTTPConnectionPool(host='host.docker.internal', port=5105): Max retries exceeded with url: /Account/Login?ReturnUrl=%2Fconnect%2Fauthorize%2Fcallback%3Fresponse_type%3Dtoken%26client_id%3Dorderingswaggerui%26redirect_uri%3Dhttp%253A%252F%252Fhost.docker.internal%253A5102%252Fswagger%252Foauth2-redirect.html%26scope%3Dorders%26state%3DTW9uIE1hciAwNiAyMDIzIDE1OjI5OjA4IEdNVCswMjAwIChJc3JhZWwgU3RhbmRhcmQgVGltZSk%253D (Caused by ConnectTimeoutError(<urllib3.connection.HTTPConnection object at 0x0000019834E25EA0>, 'Connection to host.docker.internal timed out. (connect timeout=None)'))\n               requests.exceptions.ConnectTimeout: HTTPConnectionPool(host='host.docker.internal', port=5105): Max retries exceeded with url: /Account/Login?ReturnUrl=%2Fconnect%2Fauthorize%2Fcallback%3Fresponse_type%3Dtoken%26client_id%3Dorderingswaggerui%26redirect_uri%3Dhttp%253A%252F%252Fhost.docker.internal%253A5102%252Fswagger%252Foauth2-redirect.html%26scope%3Dorders%26state%3DTW9uIE1hciAwNiAyMDIzIDE1OjI5OjA4IEdNVCswMjAwIChJc3JhZWwgU3RhbmRhcmQgVGltZSk%253D (Caused by ConnectTimeoutError(<urllib3.connection.HTTPConnection object at 0x0000019834E25EA0>, 'Connection to host.docker.internal timed out. (connect timeout=None)'))\n", "test_name": "test_user_can_ship_order_on_status_4", "rerun": "0"}, "8": {"status": "FAIL", "message": "           TimeoutError: [WinError 10060] A connection attempt failed because the connected party did not properly respond after a period of time, or established connection failed because connected host has failed to respond\n       urllib3.exceptions.ConnectTimeoutError: (<urllib3.connection.HTTPConnection object at 0x00000198352C06A0>, 'Connection to host.docker.internal timed out. (connect timeout=None)')\n       urllib3.exceptions.MaxRetryError: HTTPConnectionPool(host='host.docker.internal', port=5105): Max retries exceeded with url: /Account/Login?ReturnUrl=%2Fconnect%2Fauthorize%2Fcallback%3Fresponse_type%3Dtoken%26client_id%3Dorderingswaggerui%26redirect_uri%3Dhttp%253A%252F%252Fhost.docker.internal%253A5102%252Fswagger%252Foauth2-redirect.html%26scope%3Dorders%26state%3DTW9uIE1hciAwNiAyMDIzIDE1OjI5OjA4IEdNVCswMjAwIChJc3JhZWwgU3RhbmRhcmQgVGltZSk%253D (Caused by ConnectTimeoutError(<urllib3.connection.HTTPConnection object at 0x00000198352C06A0>, 'Connection to host.docker.internal timed out. (connect timeout=None)'))\n               requests.exceptions.ConnectTimeout: HTTPConnectionPool(host='host.docker.internal', port=5105): Max retries exceeded with url: /Account/Login?ReturnUrl=%2Fconnect%2Fauthorize%2Fcallback%3Fresponse_type%3Dtoken%26client_id%3Dorderingswaggerui%26redirect_uri%3Dhttp%253A%252F%252Fhost.docker.internal%253A5102%252Fswagger%252Foauth2-redirect.html%26scope%3Dorders%26state%3DTW9uIE1hciAwNiAyMDIzIDE1OjI5OjA4IEdNVCswMjAwIChJc3JhZWwgU3RhbmRhcmQgVGltZSk%253D (Caused by ConnectTimeoutError(<urllib3.connection.HTTPConnection object at 0x00000198352C06A0>, 'Connection to host.docker.internal timed out. (connect timeout=None)'))\n", "test_name": "test_user_can_not_ship_order_on_status_1", "rerun": "0"}, "9": {"status": "FAIL", "message": "           TimeoutError: [WinError 10060] A connection attempt failed because the connected party did not properly respond after a period of time, or established connection failed because connected host has failed to respond\n       urllib3.exceptions.ConnectTimeoutError: (<urllib3.connection.HTTPConnection object at 0x0000019834D728F0>, 'Connection to host.docker.internal timed out. (connect timeout=None)')\n       urllib3.exceptions.MaxRetryError: HTTPConnectionPool(host='host.docker.internal', port=5105): Max retries exceeded with url: /Account/Login?ReturnUrl=%2Fconnect%2Fauthorize%2Fcallback%3Fresponse_type%3Dtoken%26client_id%3Dorderingswaggerui%26redirect_uri%3Dhttp%253A%252F%252Fhost.docker.internal%253A5102%252Fswagger%252Foauth2-redirect.html%26scope%3Dorders%26state%3DTW9uIE1hciAwNiAyMDIzIDE1OjI5OjA4IEdNVCswMjAwIChJc3JhZWwgU3RhbmRhcmQgVGltZSk%253D (Caused by ConnectTimeoutError(<urllib3.connection.HTTPConnection object at 0x0000019834D728F0>, 'Connection to host.docker.internal timed out. (connect timeout=None)'))\n               requests.exceptions.ConnectTimeout: HTTPConnectionPool(host='host.docker.internal', port=5105): Max retries exceeded with url: /Account/Login?ReturnUrl=%2Fconnect%2Fauthorize%2Fcallback%3Fresponse_type%3Dtoken%26client_id%3Dorderingswaggerui%26redirect_uri%3Dhttp%253A%252F%252Fhost.docker.internal%253A5102%252Fswagger%252Foauth2-redirect.html%26scope%3Dorders%26state%3DTW9uIE1hciAwNiAyMDIzIDE1OjI5OjA4IEdNVCswMjAwIChJc3JhZWwgU3RhbmRhcmQgVGltZSk%253D (Caused by ConnectTimeoutError(<urllib3.connection.HTTPConnection object at 0x0000019834D728F0>, 'Connection to host.docker.internal timed out. (connect timeout=None)'))\n", "test_name": "test_user_can_not_ship_order_on_status_2", "rerun": "0"}, "10": {"status": "FAIL", "message": "           TimeoutError: [WinError 10060] A connection attempt failed because the connected party did not properly respond after a period of time, or established connection failed because connected host has failed to respond\n       urllib3.exceptions.ConnectTimeoutError: (<urllib3.connection.HTTPConnection object at 0x00000198350E88E0>, 'Connection to host.docker.internal timed out. (connect timeout=None)')\n       urllib3.exceptions.MaxRetryError: HTTPConnectionPool(host='host.docker.internal', port=5105): Max retries exceeded with url: /Account/Login?ReturnUrl=%2Fconnect%2Fauthorize%2Fcallback%3Fresponse_type%3Dtoken%26client_id%3Dorderingswaggerui%26redirect_uri%3Dhttp%253A%252F%252Fhost.docker.internal%253A5102%252Fswagger%252Foauth2-redirect.html%26scope%3Dorders%26state%3DTW9uIE1hciAwNiAyMDIzIDE1OjI5OjA4IEdNVCswMjAwIChJc3JhZWwgU3RhbmRhcmQgVGltZSk%253D (Caused by ConnectTimeoutError(<urllib3.connection.HTTPConnection object at 0x00000198350E88E0>, 'Connection to host.docker.internal timed out. (connect timeout=None)'))\n               requests.exceptions.ConnectTimeout: HTTPConnectionPool(host='host.docker.internal', port=5105): Max retries exceeded with url: /Account/Login?ReturnUrl=%2Fconnect%2Fauthorize%2Fcallback%3Fresponse_type%3Dtoken%26client_id%3Dorderingswaggerui%26redirect_uri%3Dhttp%253A%252F%252Fhost.docker.internal%253A5102%252Fswagger%252Foauth2-redirect.html%26scope%3Dorders%26state%3DTW9uIE1hciAwNiAyMDIzIDE1OjI5OjA4IEdNVCswMjAwIChJc3JhZWwgU3RhbmRhcmQgVGltZSk%253D (Caused by ConnectTimeoutError(<urllib3.connection.HTTPConnection object at 0x00000198350E88E0>, 'Connection to host.docker.internal timed out. (connect timeout=None)'))\n", "test_name": "test_user_can_not_ship_order_on_status_3", "rerun": "0"}, "11": {"status": "FAIL", "message": "           TimeoutError: [WinError 10060] A connection attempt failed because the connected party did not properly respond after a period of time, or established connection failed because connected host has failed to respond\n       urllib3.exceptions.ConnectTimeoutError: (<urllib3.connection.HTTPConnection object at 0x00000198352940D0>, 'Connection to host.docker.internal timed out. (connect timeout=None)')\n       urllib3.exceptions.MaxRetryError: HTTPConnectionPool(host='host.docker.internal', port=5105): Max retries exceeded with url: /Account/Login?ReturnUrl=%2Fconnect%2Fauthorize%2Fcallback%3Fresponse_type%3Dtoken%26client_id%3Dorderingswaggerui%26redirect_uri%3Dhttp%253A%252F%252Fhost.docker.internal%253A5102%252Fswagger%252Foauth2-redirect.html%26scope%3Dorders%26state%3DTW9uIE1hciAwNiAyMDIzIDE1OjI5OjA4IEdNVCswMjAwIChJc3JhZWwgU3RhbmRhcmQgVGltZSk%253D (Caused by ConnectTimeoutError(<urllib3.connection.HTTPConnection object at 0x00000198352940D0>, 'Connection to host.docker.internal timed out. (connect timeout=None)'))\n               requests.exceptions.ConnectTimeout: HTTPConnectionPool(host='host.docker.internal', port=5105): Max retries exceeded with url: /Account/Login?ReturnUrl=%2Fconnect%2Fauthorize%2Fcallback%3Fresponse_type%3Dtoken%26client_id%3Dorderingswaggerui%26redirect_uri%3Dhttp%253A%252F%252Fhost.docker.internal%253A5102%252Fswagger%252Foauth2-redirect.html%26scope%3Dorders%26state%3DTW9uIE1hciAwNiAyMDIzIDE1OjI5OjA4IEdNVCswMjAwIChJc3JhZWwgU3RhbmRhcmQgVGltZSk%253D (Caused by ConnectTimeoutError(<urllib3.connection.HTTPConnection object at 0x00000198352940D0>, 'Connection to host.docker.internal timed out. (connect timeout=None)'))\n", "test_name": "test_user_can_not_ship_order_on_status_6", "rerun": "0"}}, "status": {"total_pass": 1, "total_skip": 0, "total_xpass": 0, "total_xfail": 0, "total_rerun": 0, "total_fail": 11, "total_error": 0}}, "2": {"suite_name": "tests/suites/test_order_tracking_suite.py", "tests": {"0": {"status": "PASS", "message": "", "test_name": "test_submitted_order_status_appears_on_correct_state", "rerun": "0"}, "1": {"status": "PASS", "message": "", "test_name": "test_awatingvalidation_order_status_appears_on_correct_state", "rerun": "0"}, "2": {"status": "PASS", "message": "", "test_name": "test_stockconfirmed_order_status_appears_on_correct_state", "rerun": "0"}, "3": {"status": "PASS", "message": "", "test_name": "test_paid_order_status_appears_on_correct_state", "rerun": "0"}, "4": {"status": "FAIL", "message": "           TimeoutError: [WinError 10060] A connection attempt failed because the connected party did not properly respond after a period of time, or established connection failed because connected host has failed to respond\n       urllib3.exceptions.ConnectTimeoutError: (<urllib3.connection.HTTPConnection object at 0x0000019835457C70>, 'Connection to host.docker.internal timed out. (connect timeout=None)')\n       urllib3.exceptions.MaxRetryError: HTTPConnectionPool(host='host.docker.internal', port=5105): Max retries exceeded with url: /Account/Login?ReturnUrl=%2Fconnect%2Fauthorize%2Fcallback%3Fresponse_type%3Dtoken%26client_id%3Dorderingswaggerui%26redirect_uri%3Dhttp%253A%252F%252Fhost.docker.internal%253A5102%252Fswagger%252Foauth2-redirect.html%26scope%3Dorders%26state%3DTW9uIE1hciAwNiAyMDIzIDE1OjI5OjA4IEdNVCswMjAwIChJc3JhZWwgU3RhbmRhcmQgVGltZSk%253D (Caused by ConnectTimeoutError(<urllib3.connection.HTTPConnection object at 0x0000019835457C70>, 'Connection to host.docker.internal timed out. (connect timeout=None)'))\n               requests.exceptions.ConnectTimeout: HTTPConnectionPool(host='host.docker.internal', port=5105): Max retries exceeded with url: /Account/Login?ReturnUrl=%2Fconnect%2Fauthorize%2Fcallback%3Fresponse_type%3Dtoken%26client_id%3Dorderingswaggerui%26redirect_uri%3Dhttp%253A%252F%252Fhost.docker.internal%253A5102%252Fswagger%252Foauth2-redirect.html%26scope%3Dorders%26state%3DTW9uIE1hciAwNiAyMDIzIDE1OjI5OjA4IEdNVCswMjAwIChJc3JhZWwgU3RhbmRhcmQgVGltZSk%253D (Caused by ConnectTimeoutError(<urllib3.connection.HTTPConnection object at 0x0000019835457C70>, 'Connection to host.docker.internal timed out. (connect timeout=None)'))\n", "test_name": "test_shipped_order_status_appears_on_correct_state", "rerun": "0"}, "5": {"status": "FAIL", "message": "           TimeoutError: [WinError 10060] A connection attempt failed because the connected party did not properly respond after a period of time, or established connection failed because connected host has failed to respond\n       urllib3.exceptions.ConnectTimeoutError: (<urllib3.connection.HTTPConnection object at 0x00000198352C8850>, 'Connection to host.docker.internal timed out. (connect timeout=None)')\n       urllib3.exceptions.MaxRetryError: HTTPConnectionPool(host='host.docker.internal', port=5105): Max retries exceeded with url: /Account/Login?ReturnUrl=%2Fconnect%2Fauthorize%2Fcallback%3Fresponse_type%3Dtoken%26client_id%3Dorderingswaggerui%26redirect_uri%3Dhttp%253A%252F%252Fhost.docker.internal%253A5102%252Fswagger%252Foauth2-redirect.html%26scope%3Dorders%26state%3DTW9uIE1hciAwNiAyMDIzIDE1OjI5OjA4IEdNVCswMjAwIChJc3JhZWwgU3RhbmRhcmQgVGltZSk%253D (Caused by ConnectTimeoutError(<urllib3.connection.HTTPConnection object at 0x00000198352C8850>, 'Connection to host.docker.internal timed out. (connect timeout=None)'))\n               requests.exceptions.ConnectTimeout: HTTPConnectionPool(host='host.docker.internal', port=5105): Max retries exceeded with url: /Account/Login?ReturnUrl=%2Fconnect%2Fauthorize%2Fcallback%3Fresponse_type%3Dtoken%26client_id%3Dorderingswaggerui%26redirect_uri%3Dhttp%253A%252F%252Fhost.docker.internal%253A5102%252Fswagger%252Foauth2-redirect.html%26scope%3Dorders%26state%3DTW9uIE1hciAwNiAyMDIzIDE1OjI5OjA4IEdNVCswMjAwIChJc3JhZWwgU3RhbmRhcmQgVGltZSk%253D (Caused by ConnectTimeoutError(<urllib3.connection.HTTPConnection object at 0x00000198352C8850>, 'Connection to host.docker.internal timed out. (connect timeout=None)'))\n", "test_name": "test_canceled_order_status_appears_on_correct_state", "rerun": "0"}}, "status": {"total_pass": 4, "total_skip": 0, "total_xpass": 0, "total_xfail": 0, "total_rerun": 0, "total_fail": 2, "total_error": 0}}, "3": {"suite_name": "tests/suites/test_payment_processing_suite.py", "tests": {"0": {"status": "PASS", "message": "", "test_name": "test_payment_validation_process", "rerun": "0"}, "1": {"status": "PASS", "message": "", "test_name": "test_payment_rejection_process", "rerun": "0"}, "2": {"status": "SKIP", "message": "('C:\\\\Users\\\\ofris\\\\Desktop\\\\Ofri\\\\Ness\\\\final-project-eshop-clone\\\\rafael-ness-bootcamp\\\\tests\\\\suites\\\\test_payment_processing_suite.py', 44, 'Skipped: Designated for nightly execution.')\n", "test_name": "test_payment_process_rejection_caused_by_server_timeout", "rerun": "0"}}, "status": {"total_pass": 2, "total_skip": 1, "total_xpass": 0, "total_xfail": 0, "total_rerun": 0, "total_fail": 0, "total_error": 0}}, "4": {"suite_name": "tests/suites/test_reliability_suite.py", "tests": {"0": {"status": "FAIL", "message": "   assert 4 == 3\n", "test_name": "test_valid_data_recovery_on_crash_between_status_1_and_2", "rerun": "0"}}, "status": {"total_pass": 0, "total_skip": 0, "total_xpass": 0, "total_xfail": 0, "total_rerun": 0, "total_fail": 1, "total_error": 0}}}}, "date": "March 18, 2023", "start_time": 1679103766.7520256, "total_suite": 5, "status": "FAIL", "status_list": {"pass": "9", "fail": "14", "skip": "1", "error": "0", "xpass": "0", "xfail": "0", "rerun": "0"}, "total_tests": "24"}